Traceback (most recent call last):
  File "/rds/general/user/dla24/home/thesis/MIl/MIL_cox20.py", line 85, in <module>
    train_patches = train_patches.merge(df_train[["slide_id", "event", "os_days"]], on="slide_id", how="left")
  File "/rds/general/user/dla24/home/miniforge3/envs/thesis-hpc/lib/python3.10/site-packages/pandas/core/frame.py", line 4113, in __getitem__
    indexer = self.columns._get_indexer_strict(key, "columns")[1]
  File "/rds/general/user/dla24/home/miniforge3/envs/thesis-hpc/lib/python3.10/site-packages/pandas/core/indexes/base.py", line 6212, in _get_indexer_strict
    self._raise_if_missing(keyarr, indexer, axis_name)
  File "/rds/general/user/dla24/home/miniforge3/envs/thesis-hpc/lib/python3.10/site-packages/pandas/core/indexes/base.py", line 6264, in _raise_if_missing
    raise KeyError(f"{not_found} not in index")
KeyError: "['event'] not in index"
Traceback (most recent call last):
  File "/rds/general/user/dla24/home/thesis/MIl/MIL_cox20.py", line 85, in <module>
    train_patches = train_patches.merge(df_train[["slide_id", "event", "os_days"]], on="slide_id", how="right")
  File "/rds/general/user/dla24/home/miniforge3/envs/thesis-hpc/lib/python3.10/site-packages/pandas/core/frame.py", line 4113, in __getitem__
    indexer = self.columns._get_indexer_strict(key, "columns")[1]
  File "/rds/general/user/dla24/home/miniforge3/envs/thesis-hpc/lib/python3.10/site-packages/pandas/core/indexes/base.py", line 6212, in _get_indexer_strict
    self._raise_if_missing(keyarr, indexer, axis_name)
  File "/rds/general/user/dla24/home/miniforge3/envs/thesis-hpc/lib/python3.10/site-packages/pandas/core/indexes/base.py", line 6264, in _raise_if_missing
    raise KeyError(f"{not_found} not in index")
KeyError: "['event'] not in index"
Traceback (most recent call last):
  File "/rds/general/user/dla24/home/thesis/MIl/MIL_cox20.py", line 85, in <module>
    train_patches = train_patches.merge(df_train[["slide_id", "event", "os_days"]], on="slide_id", how="right")
  File "/rds/general/user/dla24/home/miniforge3/envs/thesis-hpc/lib/python3.10/site-packages/pandas/core/frame.py", line 4113, in __getitem__
    indexer = self.columns._get_indexer_strict(key, "columns")[1]
  File "/rds/general/user/dla24/home/miniforge3/envs/thesis-hpc/lib/python3.10/site-packages/pandas/core/indexes/base.py", line 6212, in _get_indexer_strict
    self._raise_if_missing(keyarr, indexer, axis_name)
  File "/rds/general/user/dla24/home/miniforge3/envs/thesis-hpc/lib/python3.10/site-packages/pandas/core/indexes/base.py", line 6264, in _raise_if_missing
    raise KeyError(f"{not_found} not in index")
KeyError: "['event'] not in index"
/rds/general/user/dla24/home/thesis/MIl/MIL_cox20.py:50: FutureWarning: DataFrameGroupBy.apply operated on the grouping columns. This behavior is deprecated, and in a future version of pandas the grouping columns will be excluded from the operation. Either pass `include_groups=False` to exclude the groupings or explicitly select the grouping columns after groupby to silence this warning.
  self.df = self.df.groupby("slide_id").apply(
/rds/general/user/dla24/home/thesis/MIl/MIL_cox20.py:50: FutureWarning: DataFrameGroupBy.apply operated on the grouping columns. This behavior is deprecated, and in a future version of pandas the grouping columns will be excluded from the operation. Either pass `include_groups=False` to exclude the groupings or explicitly select the grouping columns after groupby to silence this warning.
  self.df = self.df.groupby("slide_id").apply(
Traceback (most recent call last):
  File "/rds/general/user/dla24/home/miniforge3/envs/thesis-hpc/lib/python3.10/site-packages/pandas/core/indexes/base.py", line 3812, in get_loc
    return self._engine.get_loc(casted_key)
  File "pandas/_libs/index.pyx", line 167, in pandas._libs.index.IndexEngine.get_loc
  File "pandas/_libs/index.pyx", line 196, in pandas._libs.index.IndexEngine.get_loc
  File "pandas/_libs/hashtable_class_helper.pxi", line 7088, in pandas._libs.hashtable.PyObjectHashTable.get_item
  File "pandas/_libs/hashtable_class_helper.pxi", line 7096, in pandas._libs.hashtable.PyObjectHashTable.get_item
KeyError: 'time'

The above exception was the direct cause of the following exception:

Traceback (most recent call last):
  File "/rds/general/user/dla24/home/thesis/MIl/MIL_cox20.py", line 245, in <module>
    times = torch.tensor([float(val_dataset.df.iloc[idx]['time']) for idx in idxs], dtype=torch.float32).to(device)
  File "/rds/general/user/dla24/home/thesis/MIl/MIL_cox20.py", line 245, in <listcomp>
    times = torch.tensor([float(val_dataset.df.iloc[idx]['time']) for idx in idxs], dtype=torch.float32).to(device)
  File "/rds/general/user/dla24/home/miniforge3/envs/thesis-hpc/lib/python3.10/site-packages/pandas/core/series.py", line 1130, in __getitem__
    return self._get_value(key)
  File "/rds/general/user/dla24/home/miniforge3/envs/thesis-hpc/lib/python3.10/site-packages/pandas/core/series.py", line 1246, in _get_value
    loc = self.index.get_loc(label)
  File "/rds/general/user/dla24/home/miniforge3/envs/thesis-hpc/lib/python3.10/site-packages/pandas/core/indexes/base.py", line 3819, in get_loc
    raise KeyError(key) from err
KeyError: 'time'
/rds/general/user/dla24/home/thesis/MIl/MIL_cox20.py:50: FutureWarning: DataFrameGroupBy.apply operated on the grouping columns. This behavior is deprecated, and in a future version of pandas the grouping columns will be excluded from the operation. Either pass `include_groups=False` to exclude the groupings or explicitly select the grouping columns after groupby to silence this warning.
  self.df = self.df.groupby("slide_id").apply(
/rds/general/user/dla24/home/thesis/MIl/MIL_cox20.py:50: FutureWarning: DataFrameGroupBy.apply operated on the grouping columns. This behavior is deprecated, and in a future version of pandas the grouping columns will be excluded from the operation. Either pass `include_groups=False` to exclude the groupings or explicitly select the grouping columns after groupby to silence this warning.
  self.df = self.df.groupby("slide_id").apply(
Traceback (most recent call last):
  File "/rds/general/user/dla24/home/miniforge3/envs/thesis-hpc/lib/python3.10/site-packages/pandas/core/indexes/base.py", line 3812, in get_loc
    return self._engine.get_loc(casted_key)
  File "pandas/_libs/index.pyx", line 167, in pandas._libs.index.IndexEngine.get_loc
  File "pandas/_libs/index.pyx", line 196, in pandas._libs.index.IndexEngine.get_loc
  File "pandas/_libs/hashtable_class_helper.pxi", line 7088, in pandas._libs.hashtable.PyObjectHashTable.get_item
  File "pandas/_libs/hashtable_class_helper.pxi", line 7096, in pandas._libs.hashtable.PyObjectHashTable.get_item
KeyError: 'time'

The above exception was the direct cause of the following exception:

Traceback (most recent call last):
  File "/rds/general/user/dla24/home/thesis/MIl/MIL_cox20.py", line 245, in <module>
    times = torch.tensor([float(val_dataset.df.iloc[idx]['time']) for idx in idxs], dtype=torch.float32).to(device)
  File "/rds/general/user/dla24/home/thesis/MIl/MIL_cox20.py", line 245, in <listcomp>
    times = torch.tensor([float(val_dataset.df.iloc[idx]['time']) for idx in idxs], dtype=torch.float32).to(device)
  File "/rds/general/user/dla24/home/miniforge3/envs/thesis-hpc/lib/python3.10/site-packages/pandas/core/series.py", line 1130, in __getitem__
    return self._get_value(key)
  File "/rds/general/user/dla24/home/miniforge3/envs/thesis-hpc/lib/python3.10/site-packages/pandas/core/series.py", line 1246, in _get_value
    loc = self.index.get_loc(label)
  File "/rds/general/user/dla24/home/miniforge3/envs/thesis-hpc/lib/python3.10/site-packages/pandas/core/indexes/base.py", line 3819, in get_loc
    raise KeyError(key) from err
KeyError: 'time'
/rds/general/user/dla24/home/thesis/MIl/MIL_cox20.py:50: FutureWarning: DataFrameGroupBy.apply operated on the grouping columns. This behavior is deprecated, and in a future version of pandas the grouping columns will be excluded from the operation. Either pass `include_groups=False` to exclude the groupings or explicitly select the grouping columns after groupby to silence this warning.
  self.df = self.df.groupby("slide_id").apply(
/rds/general/user/dla24/home/thesis/MIl/MIL_cox20.py:50: FutureWarning: DataFrameGroupBy.apply operated on the grouping columns. This behavior is deprecated, and in a future version of pandas the grouping columns will be excluded from the operation. Either pass `include_groups=False` to exclude the groupings or explicitly select the grouping columns after groupby to silence this warning.
  self.df = self.df.groupby("slide_id").apply(
Traceback (most recent call last):
  File "/rds/general/user/dla24/home/miniforge3/envs/thesis-hpc/lib/python3.10/site-packages/pandas/core/indexes/base.py", line 3812, in get_loc
    return self._engine.get_loc(casted_key)
  File "pandas/_libs/index.pyx", line 167, in pandas._libs.index.IndexEngine.get_loc
  File "pandas/_libs/index.pyx", line 196, in pandas._libs.index.IndexEngine.get_loc
  File "pandas/_libs/hashtable_class_helper.pxi", line 7088, in pandas._libs.hashtable.PyObjectHashTable.get_item
  File "pandas/_libs/hashtable_class_helper.pxi", line 7096, in pandas._libs.hashtable.PyObjectHashTable.get_item
KeyError: 'time'

The above exception was the direct cause of the following exception:

Traceback (most recent call last):
  File "/rds/general/user/dla24/home/thesis/MIl/MIL_cox20.py", line 245, in <module>
    times = torch.tensor([float(val_dataset.df.iloc[idx]['time']) for idx in idxs], dtype=torch.float32).to(device)
  File "/rds/general/user/dla24/home/thesis/MIl/MIL_cox20.py", line 245, in <listcomp>
    times = torch.tensor([float(val_dataset.df.iloc[idx]['time']) for idx in idxs], dtype=torch.float32).to(device)
  File "/rds/general/user/dla24/home/miniforge3/envs/thesis-hpc/lib/python3.10/site-packages/pandas/core/series.py", line 1130, in __getitem__
    return self._get_value(key)
  File "/rds/general/user/dla24/home/miniforge3/envs/thesis-hpc/lib/python3.10/site-packages/pandas/core/series.py", line 1246, in _get_value
    loc = self.index.get_loc(label)
  File "/rds/general/user/dla24/home/miniforge3/envs/thesis-hpc/lib/python3.10/site-packages/pandas/core/indexes/base.py", line 3819, in get_loc
    raise KeyError(key) from err
KeyError: 'time'
/rds/general/user/dla24/home/thesis/MIl/MIL_cox20.py:50: FutureWarning: DataFrameGroupBy.apply operated on the grouping columns. This behavior is deprecated, and in a future version of pandas the grouping columns will be excluded from the operation. Either pass `include_groups=False` to exclude the groupings or explicitly select the grouping columns after groupby to silence this warning.
  self.df = self.df.groupby("slide_id").apply(
/rds/general/user/dla24/home/thesis/MIl/MIL_cox20.py:50: FutureWarning: DataFrameGroupBy.apply operated on the grouping columns. This behavior is deprecated, and in a future version of pandas the grouping columns will be excluded from the operation. Either pass `include_groups=False` to exclude the groupings or explicitly select the grouping columns after groupby to silence this warning.
  self.df = self.df.groupby("slide_id").apply(
